Workbook

Sheet Overview
A1: WDD2 Chapter 8 test log
A2: Requirement map: section, method and result. Results update from the test sheets.
A4: Req. | B4: What | C4: Section | D4: Method | E4: Result | F4: Status and notes
A5: R8 | B5: Encoder accuracy ±1° | C5: 8.2 | D5: Test | E5: ='8.2 Encoder cal'!F393 | F5: Sweep 1 (up) 12 Oct against iPhone level (±0.5°) and protractor: max error 0.37–0.61°, no zero change needed. Base hunted between ±30° (touched to settle). Repeat sweeps optional.
A6: R9 | B6: Encoder finer and more accurate than the servo | C6: 8.3 | D6: Test | E6: ='8.3 Encoder vs servo'!H34 | F6: 12 Oct: encoder noise ≤ 1 count (0.09°); servo step resolution 0.27–0.78°, reversal deadband 0.6–3.6°; encoder max error 0.37–0.61° vs servo open-loop max 0.74–3.51°.
A7: R11 | B7: Control loop ≥ 200 Hz | C7: 8.4 | D7: Test | E7: ='8.4 Control loop'!B21 | F7: Earlier T runs: I²C 1.54–1.57 ms, loop exec max 1.85–4.45 ms, 0 overruns. Step test with trim on/off to do.
A8: R10 | B8: Grasp detection 9/10 | C8: 8.5 | D8: Test | E8: ='8.5 Grasp'!D92 | F8: 12 Oct: detection (K line) correct in 70/70 trials, empty to 500 g. With the hold during a 20° lift also required: 400 g 9/10 and 500 g 9/10 (one rotation slip each), all others 10/10. Grip current 0.10–0.21 A vs 0.009 A empty.
A9: R12 | B9: Positioning ±10 mm | C9: 8.6 | D9: Test | E9: ='8.6 Accuracy'!I170 | F9: 13 Oct: 9 targets (r 250–350 mm, ±35–50°), 10 approaches each (30 at T9), pen tip as tool. Accuracy 3.1–6.4 mm, repeatability 4.7–7.0 mm, worst single approach 9.1 mm. Mean radial error −0.8 to −5.7 mm (always short); radial error grows over successive approaches (T9: −1.4 → −8.2 mm over 30). 500 g targets (T10, T11) not done.
A10: R13 | B10: Pick-and-place 9/10 within 15 s | C10: 8.7 | D10: Test | E10: ='8.7 Cycles'!F39 | F10: 13 Oct: 50 g 10/10 and 500 g 10/10 (plus 5 extra 500 g cycles, all successful). Cycle time 11.7-12.5 s. Place error 50 g 1.0-5.0 mm (mean 2.8), 500 g 1.4-8.0 mm (mean 3.7 over 15). Oscillation before the drop seen in 2/10 (50 g) and 9/15 (500 g) cycles; no significant effect on place error (p = 0.38).
A11: R1 | B11: Reach ≥ 300 mm | C11: 8.7 | D11: Test | E11: ='8.7 Cycles'!F39 | F11: Pick and place stations both at r 300 mm (±45°).
A12: R3 | B12: Payload 500 g | C12: 8.7 | D12: Test | E12: ='8.7 Cycles'!F39 | F12: 13 Oct: 500 g carried and placed in 15/15 cycles.
A13: R2 | B13: Hold 500 g at full extension | C13: 8.8 | D13: Test | E13: ='8.8 Power & safety'!B15 | F13: 13 Oct: held 500 g at full extension (all joints 0°) for 5 min. Tip sag 15 mm (pad 65 → 50 mm); shoulder −0.75°, elbow −0.63° by encoder, both trims at the +5° clamp.
A14: R5 | B14: Rails within servo ratings | C14: 8.8 | D14: Test | E14: ='8.8 Power & safety'!G23 | F14: 13 Oct, 500 g: idle / holding extended / lowest in an 8.7 cycle: shoulder 8.12 / 8.05 / 7.78 V, base+elbow 6.67 / 6.63 / 6.65 V, wrist+gripper 6.54 / 6.50 / 6.51 V, 5 V logic 5.15 / 5.06 / 5.15 V. No rail rose above idle. Multimeter only (~3 readings/s).
A15: R4 | B15: Servo temperatures | C15: 8.8 | D15: Test | E15: ='8.8 Power & safety'!E32 | F15: 13 Oct (room 19.0 °C): after 25 cycles servos 19.4–29.8 °C; after 5 min holding 500 g extended elbow 54.5 °C (+35.5), shoulder 32.1 °C, others ≤ 23.4 °C. E-stop relay 41.7–42.8 °C. Limit 60 °C is assumed; check the DS3240 rating.
A16: R6 | B16: Fuse and protection | C16: 8.8 | D16: Test + inspection | E16: ='8.8 Power & safety'!C51 | F16: Fuse intact after all tests (13 Oct). Polarity protection and transient suppression by inspection.
A17: R7 | B17: E-stop cuts servo power | C17: 8.8 | D17: Test | E17: ='8.8 Power & safety'!F48 | F17: 13 Oct: 10/10 presses during motion cut every servo rail to 0 V, GUI showed the E-stop, arm stopped in 0.20–0.34 s; ESP and 5 V stayed on; restart only after latch release + GUI Reset. GPIO 41 wire off: relay still cut the rails, but on release the arm jerked to its last pose with no reset (restart interlock relies on the signal wire).
A18: R14 | B18: GUI | C18: 8.2–8.8 | D18: Demonstration | E18: shown | F18: Used throughout the tests.
A19: R15 | B19: Cost | C19: App. | D19: Analysis | E19: see appendix | F19: Techno-economic appendix.
A20: R16 | B20: Local sourcing | C20: App. | D20: Analysis | E20: see appendix | F20: Techno-economic appendix.
A22: Suggested order
A23: 1. 8.4 loop rate (5 min, Serial Monitor only)
A24: 2. 8.3 part 1 noise and part 2 deadband (30 min)
A25: 3. 8.2 encoder calibration: one sweep, send it to me, update the zeros, then 3 verification sweeps (2–3 h)
A26: 4. 8.4 step test with the trim on and off (45 min)
A27: 5. 8.5 grasp trials (1 h)
A28: 6. 8.6 accuracy and repeatability (2–3 h, needs the mat and the pointer)
A29: 7. 8.7 pick-and-place cycles (1 h, film them)
A30: 8. 8.8 power, temperatures and E-stop (1 h, E-stop runs last, over something soft)

Sheet 8.1 Setup
A1: 8.1 Test setup
A2: Record once per test day. Not a test.
A4: Legend: yellow cells = fill in during the test. Green cells = already measured during bring-up (keep or overwrite). White cells are formulas; do not type in them. The grey example row is not counted.
A5: Item | B5: Make and model | C5: Resolution | D5: Notes
A6: Digital angle gauge / inclinometer
A7: Calipers
A8: Steel ruler
A9: Kitchen scale
A10: Multimeter
A11: IR thermometer (if borrowed)
A12: Phone (video)
A13: Printed target mat | D13: print at 100 %
A14: Printed protractor for the base | D14: 1° marks
A16: Conditions
A17: Item | B17: Value | C17: Unit | D17: Notes
A18: Test date
A19: Room temperature | C19: °C
A20: 12 V supply voltage (at the fuse) | C20: V
A21: Firmware | D21: WDD2_firmware.ino, 12 Oct 2026 (S-curve, trim, X/O/T commands)
A22: GUI | D22: ui_app.py, 11 Oct 2026 (50 Hz J sender, 50 Hz log)
A23: Encoder zeros (ZERO_RAW) | D23: 1055, 117, 645, 444 (base, shoulder, elbow, wrist)
A25: Export naming: save every GUI export as WDD2_<section>_<what>_<yyyymmdd>.xlsx, e.g. WDD2_8.6_accuracy_20261013.xlsx, and every Serial Monitor log as a .txt with the same name.

Sheet 8.2 Encoder cal
A1: 8.2 Encoder calibration (R8: ±1°, Objective 3)
A2: Shows that each AS5600 reads the true joint angle within ±1°, against an independent reference.
A4: Method:
A5: 1. Serial Monitor, GUI closed. Move a joint with M,joint,angle,40 (0 base, 1 shoulder, 2 elbow, 3 wrist). Wait 2 s, then type O,joint,2: the "mean" it prints is the encoder angle (2 s average).
A6: 2. Reference: iPhone Measure → Level, phone on its long edge, zeroed on the table (±0.5°). The level shows magnitude only: readings below horizontal are entered as negative. Positive = up.
A7: Shoulder: gauge on the upper arm. Elbow: gauge on the forearm AND on the upper arm (elbow = forearm − upper arm). Wrist: gauge on the gripper AND on the forearm. Base: printed protractor under the turntable with a pointer.
A8: 3. First do ONE upward sweep and send it to me: I work out any zero offset and update ZERO_RAW (and the servo fits, which use the same zero). Upload, then do the 3 verification sweeps below.
A9: 4. Each sweep: step up through the listed angles, then back down. Always approach in the stated direction.
A10: Pass: maximum |error| ≤ 1.0° on every joint after calibration.
A11: Legend: yellow cells = fill in during the test. Green cells = already measured during bring-up (keep or overwrite). White cells are formulas; do not type in them. The grey example row is not counted.
A12: Joint | B12: Sweep | C12: Dir | D12: Nominal (°) | E12: Gauge on this link (°) | F12: Gauge on parent link (°) | G12: Reference (°) | H12: Encoder (°) | I12: Error (°) | J12: |Error| | K12: Error² | L12: Note
A13: elbow | B13: ex | C13: up | D13: 20 | E13: 21.6 | F13: 1.2 | G13: =E13-F13 | H13: 20.6 | I13: =H13-G13
A14: base | B14: 1 | C14: up | D14: -60 | E14: -60.2 | F14: — | G14: =IF(ISNUMBER(E14),E14-IF(ISNUMBER(F14),F14,0),"") | H14: -59.59 | I14: =IF(AND(ISNUMBER(G14),ISNUMBER(H14)),H14-G14,"") | J14: =IF(ISNUMBER(I14),ABS(I14),"") | K14: =IF(ISNUMBER(I14),I14^2,"")
A15: base | B15: 1 | C15: up | D15: -50 | E15: -49.7 | F15: — | G15: =IF(ISNUMBER(E15),E15-IF(ISNUMBER(F15),F15,0),"") | H15: -50.19 | I15: =IF(AND(ISNUMBER(G15),ISNUMBER(H15)),H15-G15,"") | J15: =IF(ISNUMBER(I15),ABS(I15),"") | K15: =IF(ISNUMBER(I15),I15^2,"")
A16: base | B16: 1 | C16: up | D16: -40 | E16: -39.9 | F16: — | G16: =IF(ISNUMBER(E16),E16-IF(ISNUMBER(F16),F16,0),"") | H16: -40.15 | I16: =IF(AND(ISNUMBER(G16),ISNUMBER(H16)),H16-G16,"") | J16: =IF(ISNUMBER(I16),ABS(I16),"") | K16: =IF(ISNUMBER(I16),I16^2,"")
A17: base | B17: 1 | C17: up | D17: -30 | E17: -30.2 | F17: — | G17: =IF(ISNUMBER(E17),E17-IF(ISNUMBER(F17),F17,0),"") | H17: -30.06 | I17: =IF(AND(ISNUMBER(G17),ISNUMBER(H17)),H17-G17,"") | J17: =IF(ISNUMBER(I17),ABS(I17),"") | K17: =IF(ISNUMBER(I17),I17^2,"") | L17: hunted; touched to settle
A18: base | B18: 1 | C18: up | D18: -20 | E18: -19.7 | F18: — | G18: =IF(ISNUMBER(E18),E18-IF(ISNUMBER(F18),F18,0),"") | H18: -20.13 | I18: =IF(AND(ISNUMBER(G18),ISNUMBER(H18)),H18-G18,"") | J18: =IF(ISNUMBER(I18),ABS(I18),"") | K18: =IF(ISNUMBER(I18),I18^2,"") | L18: hunted; touched to settle
A19: base | B19: 1 | C19: up | D19: -10 | E19: -9.9 | F19: — | G19: =IF(ISNUMBER(E19),E19-IF(ISNUMBER(F19),F19,0),"") | H19: -10.02 | I19: =IF(AND(ISNUMBER(G19),ISNUMBER(H19)),H19-G19,"") | J19: =IF(ISNUMBER(I19),ABS(I19),"") | K19: =IF(ISNUMBER(I19),I19^2,"") | L19: hunted; touched to settle
A20: base | B20: 1 | C20: up | D20: 0 | E20: 0.2 | F20: — | G20: =IF(ISNUMBER(E20),E20-IF(ISNUMBER(F20),F20,0),"") | H20: 0.26 | I20: =IF(AND(ISNUMBER(G20),ISNUMBER(H20)),H20-G20,"") | J20: =IF(ISNUMBER(I20),ABS(I20),"") | K20: =IF(ISNUMBER(I20),I20^2,"") | L20: hunted; touched to settle
A21: base | B21: 1 | C21: up | D21: 10 | E21: 9.8 | F21: — | G21: =IF(ISNUMBER(E21),E21-IF(ISNUMBER(F21),F21,0),"") | H21: 9.93 | I21: =IF(AND(ISNUMBER(G21),ISNUMBER(H21)),H21-G21,"") | J21: =IF(ISNUMBER(I21),ABS(I21),"") | K21: =IF(ISNUMBER(I21),I21^2,"") | L21: hunted; touched to settle
A22: base | B22: 1 | C22: up | D22: 20 | E22: 19.8 | F22: — | G22: =IF(ISNUMBER(E22),E22-IF(ISNUMBER(F22),F22,0),"") | H22: 19.61 | I22: =IF(AND(ISNUMBER(G22),ISNUMBER(H22)),H22-G22,"") | J22: =IF(ISNUMBER(I22),ABS(I22),"") | K22: =IF(ISNUMBER(I22),I22^2,"") | L22: hunted; touched to settle
A23: base | B23: 1 | C23: up | D23: 30 | E23: 29.7 | F23: — | G23: =IF(ISNUMBER(E23),E23-IF(ISNUMBER(F23),F23,0),"") | H23: 29.79 | I23: =IF(AND(ISNUMBER(G23),ISNUMBER(H23)),H23-G23,"") | J23: =IF(ISNUMBER(I23),ABS(I23),"") | K23: =IF(ISNUMBER(I23),I23^2,"") | L23: hunted; touched to settle
A24: base | B24: 1 | C24: up | D24: 40 | E24: 40.2 | F24: — | G24: =IF(ISNUMBER(E24),E24-IF(ISNUMBER(F24),F24,0),"") | H24: 40.08 | I24: =IF(AND(ISNUMBER(G24),ISNUMBER(H24)),H24-G24,"") | J24: =IF(ISNUMBER(I24),ABS(I24),"") | K24: =IF(ISNUMBER(I24),I24^2,"")
A25: base | B25: 1 | C25: up | D25: 50 | E25: 49.8 | F25: — | G25: =IF(ISNUMBER(E25),E25-IF(ISNUMBER(F25),F25,0),"") | H25: 50.01 | I25: =IF(AND(ISNUMBER(G25),ISNUMBER(H25)),H25-G25,"") | J25: =IF(ISNUMBER(I25),ABS(I25),"") | K25: =IF(ISNUMBER(I25),I25^2,"")
A26: base | B26: 1 | C26: up | D26: 60 | E26: 60.1 | F26: — | G26: =IF(ISNUMBER(E26),E26-IF(ISNUMBER(F26),F26,0),"") | H26: 60.03 | I26: =IF(AND(ISNUMBER(G26),ISNUMBER(H26)),H26-G26,"") | J26: =IF(ISNUMBER(I26),ABS(I26),"") | K26: =IF(ISNUMBER(I26),I26^2,"")
A27: base | B27: 1 | C27: down | D27: 60 | F27: — | G27: =IF(ISNUMBER(E27),E27-IF(ISNUMBER(F27),F27,0),"") | I27: =IF(AND(ISNUMBER(G27),ISNUMBER(H27)),H27-G27,"") | J27: =IF(ISNUMBER(I27),ABS(I27),"") | K27: =IF(ISNUMBER(I27),I27^2,"")
A28: base | B28: 1 | C28: down | D28: 50 | F28: — | G28: =IF(ISNUMBER(E28),E28-IF(ISNUMBER(F28),F28,0),"") | I28: =IF(AND(ISNUMBER(G28),ISNUMBER(H28)),H28-G28,"") | J28: =IF(ISNUMBER(I28),ABS(I28),"") | K28: =IF(ISNUMBER(I28),I28^2,"")
A29: base | B29: 1 | C29: down | D29: 40 | F29: — | G29: =IF(ISNUMBER(E29),E29-IF(ISNUMBER(F29),F29,0),"") | I29: =IF(AND(ISNUMBER(G29),ISNUMBER(H29)),H29-G29,"") | J29: =IF(ISNUMBER(I29),ABS(I29),"") | K29: =IF(ISNUMBER(I29),I29^2,"")
A30: base | B30: 1 | C30: down | D30: 30 | F30: — | G30: =IF(ISNUMBER(E30),E30-IF(ISNUMBER(F30),F30,0),"") | I30: =IF(AND(ISNUMBER(G30),ISNUMBER(H30)),H30-G30,"") | J30: =IF(ISNUMBER(I30),ABS(I30),"") | K30: =IF(ISNUMBER(I30),I30^2,"")
A31: base | B31: 1 | C31: down | D31: 20 | F31: — | G31: =IF(ISNUMBER(E31),E31-IF(ISNUMBER(F31),F31,0),"") | I31: =IF(AND(ISNUMBER(G31),ISNUMBER(H31)),H31-G31,"") | J31: =IF(ISNUMBER(I31),ABS(I31),"") | K31: =IF(ISNUMBER(I31),I31^2,"")
A32: base | B32: 1 | C32: down | D32: 10 | F32: — | G32: =IF(ISNUMBER(E32),E32-IF(ISNUMBER(F32),F32,0),"") | I32: =IF(AND(ISNUMBER(G32),ISNUMBER(H32)),H32-G32,"") | J32: =IF(ISNUMBER(I32),ABS(I32),"") | K32: =IF(ISNUMBER(I32),I32^2,"")
A33: base | B33: 1 | C33: down | D33: 0 | F33: — | G33: =IF(ISNUMBER(E33),E33-IF(ISNUMBER(F33),F33,0),"") | I33: =IF(AND(ISNUMBER(G33),ISNUMBER(H33)),H33-G33,"") | J33: =IF(ISNUMBER(I33),ABS(I33),"") | K33: =IF(ISNUMBER(I33),I33^2,"")
A34: base | B34: 1 | C34: down | D34: -10 | F34: — | G34: =IF(ISNUMBER(E34),E34-IF(ISNUMBER(F34),F34,0),"") | I34: =IF(AND(ISNUMBER(G34),ISNUMBER(H34)),H34-G34,"") | J34: =IF(ISNUMBER(I34),ABS(I34),"") | K34: =IF(ISNUMBER(I34),I34^2,"")
A35: base | B35: 1 | C35: down | D35: -20 | F35: — | G35: =IF(ISNUMBER(E35),E35-IF(ISNUMBER(F35),F35,0),"") | I35: =IF(AND(ISNUMBER(G35),ISNUMBER(H35)),H35-G35,"") | J35: =IF(ISNUMBER(I35),ABS(I35),"") | K35: =IF(ISNUMBER(I35),I35^2,"")
A36: base | B36: 1 | C36: down | D36: -30 | F36: — | G36: =IF(ISNUMBER(E36),E36-IF(ISNUMBER(F36),F36,0),"") | I36: =IF(AND(ISNUMBER(G36),ISNUMBER(H36)),H36-G36,"") | J36: =IF(ISNUMBER(I36),ABS(I36),"") | K36: =IF(ISNUMBER(I36),I36^2,"")
A37: base | B37: 1 | C37: down | D37: -40 | F37: — | G37: =IF(ISNUMBER(E37),E37-IF(ISNUMBER(F37),F37,0),"") | I37: =IF(AND(ISNUMBER(G37),ISNUMBER(H37)),H37-G37,"") | J37: =IF(ISNUMBER(I37),ABS(I37),"") | K37: =IF(ISNUMBER(I37),I37^2,"")
A38: base | B38: 1 | C38: down | D38: -50 | F38: — | G38: =IF(ISNUMBER(E38),E38-IF(ISNUMBER(F38),F38,0),"") | I38: =IF(AND(ISNUMBER(G38),ISNUMBER(H38)),H38-G38,"") | J38: =IF(ISNUMBER(I38),ABS(I38),"") | K38: =IF(ISNUMBER(I38),I38^2,"")
... A91: base | B91: 3 | C91: down | D91: -60 | F91: — | G91: =IF(ISNUMBER(E91),E91-IF(ISNUMBER(F91),F91,0),"") | I91: =IF(AND(ISNUMBER(G91),ISNUMBER(H91)),H91-G91,"") | J91: =IF(ISNUMBER(I91),ABS(I91),"") | K91: =IF(ISNUMBER(I91),I91^2,"")
A92: shoulder | B92: 1 | C92: up | D92: -30 | E92: -29.6 | F92: — | G92: =IF(ISNUMBER(E92),E92-IF(ISNUMBER(F92),F92,0),"") | H92: -29.97 | I92: =IF(AND(ISNUMBER(G92),ISNUMBER(H92)),H92-G92,"") | J92: =IF(ISNUMBER(I92),ABS(I92),"") | K92: =IF(ISNUMBER(I92),I92^2,"")
A93: shoulder | B93: 1 | C93: up | D93: -20 | E93: -20.4 | F93: — | G93: =IF(ISNUMBER(E93),E93-IF(ISNUMBER(F93),F93,0),"") | H93: -20.31 | I93: =IF(AND(ISNUMBER(G93),ISNUMBER(H93)),H93-G93,"") | J93: =IF(ISNUMBER(I93),ABS(I93),"") | K93: =IF(ISNUMBER(I93),I93^2,"")
...

Sheet 8.3 Encoder vs servo
A1: 8.3 Encoder versus servo command (R9, Objective 4)
A2: There is no servo feedback wire, so the encoder is compared with the servo command. Say so in the text.
A4: Part 1, encoder resolution (firmware, Serial Monitor):
A5: Move the joint to a mid pose (M,joint,angle,40), wait 3 s, then type O,joint,60. Record the std and peak-to-peak it prints.
A6: Part 2, servo deadband (BRING-UP sketch, because it takes pulse widths in µs):
A7: Approach the start pulse from 20 µs below (e.g. p2 1542 then p2 1562), type m<n>, then step DOWN 1 µs at a time (about 3 s each). The first pulse where the raw count changes and stays changed is the reversal point (deadband plus backlash). Keep stepping and note the µs between the next jumps: that is the step resolution.
A8: Part 3, open-loop servo error: from the bring-up fits (pre-filled, green).
A9: Pass: encoder std (part 1) < servo step resolution (part 2, in degrees), and encoder max error (8.2) < open-loop servo max error.
A10: Legend: yellow cells = fill in during the test. Green cells = already measured during bring-up (keep or overwrite). White cells are formulas; do not type in them. The grey example row is not counted.
A11: Part 1: encoder resolution (60 s hold)
A12: Joint | B12: Pose (°) | C12: Std (°) | D12: Peak-to-peak (°) | E12: Theory: 1 count (°) | F12: Note
A13: example | B13: 30 | C13: 0.03 | D13: 0.09 | E13: =360/4096
A14: base | B14: 30 | C14: 0 | D14: 0.09 | E14: =360/4096 | F14: 12 Oct 2026, 60 s re-run (fixed firmware): std 0.00, p2p 0.00. First run flickered 1 count (0.09), kept as worst case
A15: shoulder | B15: 30 | C15: 0 | D15: 0.09 | E15: =360/4096 | F15: 12 Oct 2026, 60 s re-run (fixed firmware): std 0.00, p2p 0.00. First run flickered 1 count (0.09), kept as worst case
A16: elbow | B16: 0 | C16: 0 | D16: 0 | E16: =360/4096 | F16: 12 Oct 2026, 60 s
A17: wrist | B17: 0 | C17: 0 | D17: 0 | E17: =360/4096 | F17: 12 Oct 2026, 60 s
A19: Part 2: servo deadband (1 µs steps)
A20: Joint | B20: Start pulse (µs) | C20: Reversal: first move (µs) | D20: Step resolution (µs) | E20: Slope k (°/µs) | F20: Reversal deadband (°) | G20: Step resolution (°) | H20: Note
A21: example | B21: 1562 | C21: 1556 | D21: 2 | E21: 0.1358
A22: base | B22: 1623 | C22: 1618 | D22: 4 | E22: 0.1276 | F22: =IF(ISNUMBER(C22),ABS(B22-C22)*E22,"") | G22: =IF(ISNUMBER(D22),D22*E22,"") | H22: Hunts ±0.7° for several s after each step (horn play); jumps every 3–5 µs
A23: shoulder | B23: 1558 | C23: 1530 | D23: 6 | E23: 0.1292 | F23: =IF(ISNUMBER(C23),ABS(B23-C23)*E23,"") | G23: =IF(ISNUMBER(D23),D23*E23,"") | H23: Stick-slip: 0.5–0.8° jumps, up to 2 s delay
A24: elbow | B24: 1582 | C24: 1576 | D24: 2 | E24: 0.1358 | F24: =IF(ISNUMBER(C24),ABS(B24-C24)*E24,"") | G24: =IF(ISNUMBER(D24),D24*E24,"") | H24: Start 1582 approached from below; step size from 1562→1564 up test
A25: wrist | B25: 1548 | C25: 1539 | D25: 3.5 | E25: 0.1361 | F25: =IF(ISNUMBER(C25),ABS(B25-C25)*E25,"") | G25: =IF(ISNUMBER(D25),D25*E25,"") | H25: 1 count creep at 1541; jumps every 3–4 µs
A26: Slope k: magnitude of the bring-up fits (9 and 11 Oct 2026). Measured 12 Oct 2026 with the bring-up sketch, shoulder and elbow at 0°.
A28: Part 3: open-loop servo error (bring-up fits) against encoder error (8.2)
A29: Joint | B29: Servo fit RMS (°) | C29: Servo fit max (°) | D29: Servo hysteresis (°) | E29: Encoder max error, 8.2 (°) | F29: Encoder std, part 1 (°) | G29: Servo step resolution, part 2 (°) | H29: Result
A30: base | B30: 0.45 | C30: 0.74 | D30: 0.5 | E30: ='8.2 Encoder cal'!D389 | F30: =C14 | G30: =G22 | H30: =IF(OR(NOT(ISNUMBER(E30)),NOT(ISNUMBER(F30))),"not done",IF(AND(E30<C30,OR(NOT(ISNUMBER(G30)),F30<G30)),"PASS","FAIL"))
A31: shoulder | B31: 1.6 | C31: 2.96 | D31: 3.2 | E31: ='8.2 Encoder cal'!D390 | F31: =C15 | G31: =G23 | H31: =IF(OR(NOT(ISNUMBER(E31)),NOT(ISNUMBER(F31))),"not done",IF(AND(E31<C31,OR(NOT(ISNUMBER(G31)),F31<G31)),"PASS","FAIL"))
A32: elbow | B32: 0.41 | C32: 0.9 | D32: 1.3 | E32: ='8.2 Encoder cal'!D391 | F32: =C16 | G32: =G24 | H32: =IF(OR(NOT(ISNUMBER(E32)),NOT(ISNUMBER(F32))),"not done",IF(AND(E32<C32,OR(NOT(ISNUMBER(G32)),F32<G32)),"PASS","FAIL"))
A33: wrist | B33: 1.26 | C33: 3.51 | D33: 0.7 | E33: ='8.2 Encoder cal'!D392 | F33: =C17 | G33: =G25 | H33: =IF(OR(NOT(ISNUMBER(E33)),NOT(ISNUMBER(F33))),"not done",IF(AND(E33<C33,OR(NOT(ISNUMBER(G33)),F33<G33)),"PASS","FAIL"))
A34: All joints | H34: =IF(COUNTIF(H30:H33,"not done")>0,"not done",IF(COUNTIF(H30:H33,"FAIL")>0,"FAIL","PASS"))
A35: Green: base fit 11 Oct (11 points, 2200 µs point excluded); shoulder, elbow and wrist fits 9 Oct 2026. Hysteresis = spread of readings at the same pulse.

Sheet 8.4 Control loop
A1: 8.4 Control loop (R11: ≥ 200 Hz, Objective 6)
A2: Loop timing, then a step test with the trim loop on and off.
A4: Part 1, loop rate: Serial Monitor. Type T, wait at least 60 s (12 000 loops), type T again and copy the second output here. The firmware times every loop with micros().
A5: Pass: mean period ≤ 5000 µs (≥ 200 Hz), every loop finishes inside its 5 ms (exec max < 5000 µs) and 0 overruns.
A6: Part 2, step test (shoulder, elbow, wrist with and without 500 g; base without load, from 35° because it hunts inside ±30°):
A7: X,joint,1 (trim on). M,joint,start,180, wait 3 s. M,joint,start+10,180, wait 5 s. Back to start. Repeat 3 times. Then X,joint,0 (trim off) and repeat. Then with 500 g in the gripper. Send me the Serial Monitor log: I extract settling time, overshoot and final error from the A lines and fill the yellow cells (or read final error with P).
A8: Settling time: until the joint stays within ±0.5° of its final value. Final error: encoder − target, 5 s after the step.
A9: Legend: yellow cells = fill in during the test. Green cells = already measured during bring-up (keep or overwrite). White cells are formulas; do not type in them. The grey example row is not counted.
A10: Part 1: loop timing (from T)
A11: Quantity | B11: Value | C11: Unit | D11: Note
A12: Loops measured | B12: 22773
A13: Mean loop period | B13: 5000 | C13: µs | D13: 12 Oct 2026, 114 s run incl. moves
A14: Min loop period | B14: 4717 | C14: µs
A15: Max loop period | B15: 5283 | C15: µs
A16: I²C read mean (4 encoders + INA219) | B16: 1472 | C16: µs | D16: earlier: 1544–1565 µs
A17: I²C read max | B17: 1675 | C17: µs | D17: earlier: 1631–4062 µs
A18: Loop exec max | B18: 1965 | C18: µs | D18: earlier: 1852–4453 µs
A19: Overruns | B19: 0 | D19: earlier: 0
A20: Mean rate | B20: =IF(ISNUMBER(B13),1000000/B13,"") | C20: Hz
A21: Result | B21: =IF(NOT(ISNUMBER(B13)),"not done",IF(AND(B13<=5000.5,B18<5000,B19=0),"PASS","FAIL"))
A23: Part 2: step test (+10° steps)
A24: Joint | B24: Load | C24: Trim | D24: Rep | E24: Start (°) | F24: Settling time (s) | G24: Overshoot (°) | H24: Final error (°) | I24: |Final error| | J24: Return step (S+10 → S): settle s / overshoot / final error
A25: example | B25: 0 g | C25: on | D25: 1 | E25: 20 | F25: 0.45 | G25: 0.6 | H25: 0.2
A26: base | B26: 0 g | C26: on | D26: 1 | E26: 35 | F26: 0.32 | G26: 1.01 | H26: 0.08 | I26: =IF(ISNUMBER(H26),ABS(H26),"") | J26: 0.52 s / 0.81° / -0.47°
A27: base | B27: 0 g | C27: on | D27: 2 | E27: 35 | F27: 0.36 | G27: 1.03 | H27: 0.11 | I27: =IF(ISNUMBER(H27),ABS(H27),"") | J27: 0.7 s / 0.99° / -0.21°
A28: base | B28: 0 g | C28: on | D28: 3 | E28: 35 | F28: 0.3 | G28: 0.83 | H28: 0.18 | I28: =IF(ISNUMBER(H28),ABS(H28),"") | J28: 0.52 s / 0.99° / -0.54°
A29: base | B29: 0 g | C29: off | D29: 1 | E29: 35 | F29: 0.32 | G29: 1.08 | H29: 0 | I29: =IF(ISNUMBER(H29),ABS(H29),"") | J29: 0.76 s / 0.55° / -0.20°
A30: base | B30: 0 g | C30: off | D30: 2 | E30: 35 | F30: 0.28 | G30: 0.79 | H30: 0.18 | I30: =IF(ISNUMBER(H30),ABS(H30),"") | J30: 0.78 s / 0.72° / -0.28°
A31: base | B31: 0 g | C31: off | D31: 3 | E31: 35 | F31: 0.28 | G31: 0.79 | H31: 0.26 | I31: =IF(ISNUMBER(H31),ABS(H31),"") | J31: 0.78 s / 0.66° / -0.28°
A32: shoulder | B32: 0 g | C32: on | D32: 1 | E32: 20 | F32: 3.12 | G32: 1.2 | H32: -0.55 | I32: =IF(ISNUMBER(H32),ABS(H32),"") | J32: 3.32 s / 1.19° / -1.12°
A33: shoulder | B33: 0 g | C33: on | D33: 2 | E33: 20 | F33: 2.62 | G33: 1.29 | H33: -0.38 | I33: =IF(ISNUMBER(H33),ABS(H33),"") | J33: 0.4 s / 0.58° / -0.50°
A34: shoulder | B34: 0 g | C34: on | D34: 3 | E34: 20 | F34: 2.66 | G34: 1.29 | H34: -0.56 | I34: =IF(ISNUMBER(H34),ABS(H34),"") | J34: 0.4 s / 0.0° / +0.30°
A35: shoulder | B35: 0 g | C35: off | D35: 1 | E35: 20 | F35: 0.42 | G35: 0 | H35: -2.4 | I35: =IF(ISNUMBER(H35),ABS(H35),"") | J35: 0.32 s / 0.0° / +0.30°
A36: shoulder | B36: 0 g | C36: off | D36: 2 | E36: 20 | F36: 0.4 | G36: 0 | H36: -2.58 | I36: =IF(ISNUMBER(H36),ABS(H36),"") | J36: 0.36 s / 0.22° / -0.22°
A37: shoulder | B37: 0 g | C37: off | D37: 3 | E37: 20 | F37: 0.38 | G37: 0 | H37: -2.4 | I37: =IF(ISNUMBER(H37),ABS(H37),"") | J37: 0.36 s / 0.22° / -0.22°
... A67: wrist | B67: 500 g | C67: off | D67: 3 | E67: 20 | F67: 1.42 | G67: 0 | H67: -1.7 | I67: =IF(ISNUMBER(H67),ABS(H67),"") | J67: 0.24 s / 1.63° / -1.37°
A69: Summary: mean |final error| (°)
A70: Joint | B70: Load | C70: Trim on | D70: Trim off | E70: Improvement | F70: Mean settle on (s) | G70: Mean settle off (s)
A71: base | B71: 0 g | C71: =IFERROR(AVERAGEIFS($I$26:$I$67,$A$26:$A$67,"base",$B$26:$B$67,"0 g",$C$26:$C$67,"on"),"") | D71: =IFERROR(AVERAGEIFS($I$26:$I$67,$A$26:$A$67,"base",$B$26:$B$67,"0 g",$C$26:$C$67,"off"),"") | E71: =IF(AND(ISNUMBER(C71),ISNUMBER(D71)),D71-C71,"") | F71: =IFERROR(AVERAGEIFS($F$26:$F$67,$A$26:$A$67,"base",$B$26:$B$67,"0 g",$C$26:$C$67,"on"),"") | G71: =IFERROR(AVERAGEIFS($F$26:$F$67,$A$26:$A$67,"base",$B$26:$B$67,"0 g",$C$26:$C$67,"off"),"")
A72: shoulder | B72: 0 g | C72: =IFERROR(AVERAGEIFS($I$26:$I$67,$A$26:$A$67,"shoulder",$B$26:$B$67,"0 g",$C$26:$C$67,"on"),"") | D72: =IFERROR(AVERAGEIFS($I$26:$I$67,$A$26:$A$67,"shoulder",$B$26:$B$67,"0 g",$C$26:$C$67,"off"),"") | E72: =IF(AND(ISNUMBER(C72),ISNUMBER(D72)),D72-C72,"") | F72: =IFERROR(AVERAGEIFS($F$26:$F$67,$A$26:$A$67,"shoulder",$B$26:$B$67,"0 g",$C$26:$C$67,"on"),"") | G72: =IFERROR(AVERAGEIFS($F$26:$F$67,$A$26:$A$67,"shoulder",$B$26:$B$67,"0 g",$C$26:$C$67,"off"),"")
...

Sheet 8.5 Grasp
A1: 8.5 Grasp detection (R10: 9 of 10)
A2: Detection rule in the firmware: wait 450 ms after G,1, then the median current over 200 ms must exceed 0.04 A.
A4: Method (Serial Monitor): arm at the pick pose, gripper open (G,0). Place the payload between the jaws, send G,1 and note the K line (K,1 = grasp, K,0 = failed) and the median current it prints. Then lift 20° with the shoulder (M,1,<pose+20>,40), hold 3 s, come back, G,0.
A5: Empty closures: G,1 with nothing in the jaws. Correct if the firmware answers K,0 (it re-opens by itself).
A6: A "grasp detected" where the cube then slips counts as a failure.
A7: Also export one current trace of a grasp and one of an empty closure (bring-up sketch: c 950) for the figure.
A8: Pass: at least 9 of 10 correct for every payload and for the empty closures.
A9: Legend: yellow cells = fill in during the test. Green cells = already measured during bring-up (keep or overwrite). White cells are formulas; do not type in them. The grey example row is not counted. | I9: Payload make-up (masses weighed 12 Oct 2026)
A10: Payload | B10: Trial | C10: K result (1 or 0) | D10: Held during lift (Y/N) | E10: Correct? | F10: Median I (A) | G10: Notes | H10: Detection correct? | I10: Payload | J10: Items | K10: Sum of items (g) | L10: Weighed total (g)
A11: 50 g | B11: ex | C11: 1 | D11: Y | E11: yes | F11: 0.11 | I11: 50 g | J11: cube + 1 oz #1 | K11: =24+28
A12: empty | B12: 1 | C12: 0 | D12: — | E12: =IF(C12="","",IF(C12=0,"yes","no")) | F12: 0.009 | G12: 12 Oct 2026, all 10 K,0 and re-opened | H12: =IF(C12="","",IF(A12="empty",IF(C12=0,"yes","no"),IF(C12=1,"yes","no"))) | I12: 100 g | J12: cube + bearing 1 + 2 oz | K12: =24+10+60
A13: empty | B13: 2 | C13: 0 | D13: — | E13: =IF(C13="","",IF(C13=0,"yes","no")) | F13: 0.009 | H13: =IF(C13="","",IF(A13="empty",IF(C13=0,"yes","no"),IF(C13=1,"yes","no"))) | I13: 200 g | J13: cube + 2 oz + 4 oz #3 | K13: =24+60+113
A14: empty | B14: 3 | C14: 0 | D14: — | E14: =IF(C14="","",IF(C14=0,"yes","no")) | F14: 0.009 | H14: =IF(C14="","",IF(A14="empty",IF(C14=0,"yes","no"),IF(C14=1,"yes","no"))) | I14: 300 g | J14: cube + 4 oz #2 + 4 oz #3 + 2 oz | K14: =24+109+113+60
A15: empty | B15: 4 | C15: 0 | D15: — | E15: =IF(C15="","",IF(C15=0,"yes","no")) | F15: 0.009 | H15: =IF(C15="","",IF(A15="empty",IF(C15=0,"yes","no"),IF(C15=1,"yes","no"))) | I15: 400 g | J15: cube + 3 × 4 oz + 1 oz #2 + bearing 1 | K15: =24+116+109+113+27+10
A16: empty | B16: 5 | C16: 0 | D16: — | E16: =IF(C16="","",IF(C16=0,"yes","no")) | F16: 0.009 | H16: =IF(C16="","",IF(A16="empty",IF(C16=0,"yes","no"),IF(C16=1,"yes","no"))) | I16: 500 g | J16: cube + 3 × 4 oz + 2 oz + 2 × 1 oz + 2 bearings | K16: =24+116+109+113+60+28+27+10+11
A17: empty | B17: 6 | C17: 0 | D17: — | E17: =IF(C17="","",IF(C17=0,"yes","no")) | F17: 0.009 | H17: =IF(C17="","",IF(A17="empty",IF(C17=0,"yes","no"),IF(C17=1,"yes","no"))) | I17: Items: cube 24 g, bearings 10 g and 11 g, 1 oz 28 g and 27 g, 2 oz 60 g, 4 oz 116 g, 109 g, 113 g. Weigh each assembled payload (with its tape) and enter it in the yellow column.
A18: empty | B18: 7 | C18: 0 | D18: — | E18: =IF(C18="","",IF(C18=0,"yes","no")) | F18: 0.009 | H18: =IF(C18="","",IF(A18="empty",IF(C18=0,"yes","no"),IF(C18=1,"yes","no")))
A19: empty | B19: 8 | C19: 0 | D19: — | E19: =IF(C19="","",IF(C19=0,"yes","no")) | F19: 0.009 | H19: =IF(C19="","",IF(A19="empty",IF(C19=0,"yes","no"),IF(C19=1,"yes","no")))
A20: empty | B20: 9 | C20: 0 | D20: — | E20: =IF(C20="","",IF(C20=0,"yes","no")) | F20: 0.009 | H20: =IF(C20="","",IF(A20="empty",IF(C20=0,"yes","no"),IF(C20=1,"yes","no")))
A21: empty | B21: 10 | C21: 0 | D21: — | E21: =IF(C21="","",IF(C21=0,"yes","no")) | F21: 0.009 | H21: =IF(C21="","",IF(A21="empty",IF(C21=0,"yes","no"),IF(C21=1,"yes","no")))
A22: 50 g | B22: 1 | C22: 1 | D22: Y | E22: =IF(C22="","",IF(AND(C22=1,D22="Y"),"yes","no")) | F22: 0.115 | H22: =IF(C22="","",IF(A22="empty",IF(C22=0,"yes","no"),IF(C22=1,"yes","no")))
A23: 50 g | B23: 2 | C23: 1 | D23: Y | E23: =IF(C23="","",IF(AND(C23=1,D23="Y"),"yes","no")) | F23: 0.128 | H23: =IF(C23="","",IF(A23="empty",IF(C23=0,"yes","no"),IF(C23=1,"yes","no")))
A24: 50 g | B24: 3 | C24: 1 | D24: Y | E24: =IF(C24="","",IF(AND(C24=1,D24="Y"),"yes","no")) | F24: 0.134 | H24: =IF(C24="","",IF(A24="empty",IF(C24=0,"yes","no"),IF(C24=1,"yes","no")))
A25: 50 g | B25: 4 | C25: 1 | D25: Y | E25: =IF(C25="","",IF(AND(C25=1,D25="Y"),"yes","no")) | F25: 0.145 | H25: =IF(C25="","",IF(A25="empty",IF(C25=0,"yes","no"),IF(C25=1,"yes","no")))
A26: 50 g | B26: 5 | C26: 1 | D26: Y | E26: =IF(C26="","",IF(AND(C26=1,D26="Y"),"yes","no")) | F26: 0.128 | H26: =IF(C26="","",IF(A26="empty",IF(C26=0,"yes","no"),IF(C26=1,"yes","no")))
A27: 50 g | B27: 6 | C27: 1 | D27: Y | E27: =IF(C27="","",IF(AND(C27=1,D27="Y"),"yes","no")) | F27: 0.118 | H27: =IF(C27="","",IF(A27="empty",IF(C27=0,"yes","no"),IF(C27=1,"yes","no")))
A28: 50 g | B28: 7 | C28: 1 | D28: Y | E28: =IF(C28="","",IF(AND(C28=1,D28="Y"),"yes","no")) | F28: 0.114 | H28: =IF(C28="","",IF(A28="empty",IF(C28=0,"yes","no"),IF(C28=1,"yes","no")))
A29: 50 g | B29: 8 | C29: 1 | D29: Y | E29: =IF(C29="","",IF(AND(C29=1,D29="Y"),"yes","no")) | F29: 0.102 | H29: =IF(C29="","",IF(A29="empty",IF(C29=0,"yes","no"),IF(C29=1,"yes","no")))
A30: 50 g | B30: 9 | C30: 1 | D30: Y | E30: =IF(C30="","",IF(AND(C30=1,D30="Y"),"yes","no")) | F30: 0.122 | H30: =IF(C30="","",IF(A30="empty",IF(C30=0,"yes","no"),IF(C30=1,"yes","no")))
A31: 50 g | B31: 10 | C31: 1 | D31: Y | E31: =IF(C31="","",IF(AND(C31=1,D31="Y"),"yes","no")) | F31: 0.116 | H31: =IF(C31="","",IF(A31="empty",IF(C31=0,"yes","no"),IF(C31=1,"yes","no")))
A32: 100 g | B32: 1 | C32: 1 | D32: Y | E32: =IF(C32="","",IF(AND(C32=1,D32="Y"),"yes","no")) | F32: 0.116 | H32: =IF(C32="","",IF(A32="empty",IF(C32=0,"yes","no"),IF(C32=1,"yes","no")))
A33: 100 g | B33: 2 | C33: 1 | D33: Y | E33: =IF(C33="","",IF(AND(C33=1,D33="Y"),"yes","no")) | F33: 0.109 | H33: =IF(C33="","",IF(A33="empty",IF(C33=0,"yes","no"),IF(C33=1,"yes","no")))
... A40: 100 g | B40: 9 | C40: 1 | D40: Y | E40: =IF(C40="","",IF(AND(C40=1,D40="Y"),"yes","no")) | F40: 0.122 | H40: =IF(C40="","",IF(A40="empty",IF(C40=0,"yes","no"),IF(C40=1,"yes","no")))
A41: 100 g | B41: 10 | C41: 1 | D41: Y | E41: =IF(C41="","",IF(AND(C41=1,D41="Y"),"yes","no")) | F41: 0.115 | G41: an 11th trial was also run: K,1, 0.108 A, held (11/11) | H41: =IF(C41="","",IF(A41="empty",IF(C41=0,"yes","no"),IF(C41=1,"yes","no")))
A42: 200 g | B42: 1 | C42: 1 | D42: Y | E42: =IF(C42="","",IF(AND(C42=1,D42="Y"),"yes","no")) | F42: 0.138 | H42: =IF(C42="","",IF(A42="empty",IF(C42=0,"yes","no"),IF(C42=1,"yes","no")))
A43: 200 g | B43: 2 | C43: 1 | D43: Y | E43: =IF(C43="","",IF(AND(C43=1,D43="Y"),"yes","no")) | F43: 0.115 | H43: =IF(C43="","",IF(A43="empty",IF(C43=0,"yes","no"),IF(C43=1,"yes","no")))
A44: 200 g | B44: 3 | C44: 1 | D44: Y | E44: =IF(C44="","",IF(AND(C44=1,D44="Y"),"yes","no")) | F44: 0.108 | H44: =IF(C44="","",IF(A44="empty",IF(C44=0,"yes","no"),IF(C44=1,"yes","no")))
A45: 200 g | B45: 4 | C45: 1 | D45: Y | E45: =IF(C45="","",IF(AND(C45=1,D45="Y"),"yes","no")) | F45: 0.108 | H45: =IF(C45="","",IF(A45="empty",IF(C45=0,"yes","no"),IF(C45=1,"yes","no")))
A46: 200 g | B46: 5 | C46: 1 | D46: Y | E46: =IF(C46="","",IF(AND(C46=1,D46="Y"),"yes","no")) | F46: 0.114 | H46: =IF(C46="","",IF(A46="empty",IF(C46=0,"yes","no"),IF(C46=1,"yes","no")))
A47: 200 g | B47: 6 | C47: 1 | D47: Y | E47: =IF(C47="","",IF(AND(C47=1,D47="Y"),"yes","no")) | F47: 0.11 | H47: =IF(C47="","",IF(A47="empty",IF(C47=0,"yes","no"),IF(C47=1,"yes","no")))
...

Sheet 8.6 Accuracy
A1: 8.6 Positioning accuracy and repeatability (R12: ±10 mm, Objective 7)
A2: ISO 9283 style: accuracy = distance from the target to the mean position; repeatability = mean distance from the centroid + 3 standard deviations.
A4: Setup: target mat with crosses measured from the BASE AXIS. A pointer (pin, dowel or pen) in the jaws with its tip at the TCP. Enter each target in the GUI (Cartesian target) and run it from the same home pose every time.
A5: Each target: approaches from home via a point above the target. Read the tip offset from the cross along the target ray: radial (+ = beyond the target, − = short) and lateral (+ = right of the ray, − = left, seen from the base looking out along the ray), in mm.
A6: Allow about 2 s for the base to settle before marking. T10 and T11 repeat T9 and T7 with 500 g in the gripper (sag).
A7: Pass: accuracy ≤ 10 mm at every target. Compare with the 54 mm reported by Al Tahtawi et al.
A8: Legend: yellow cells = fill in during the test. Green cells = already measured during bring-up (keep or overwrite). White cells are formulas; do not type in them. The grey example row is not counted.
A9: Targets
A10: Target | C10: Radius (mm) | D10: Base angle (°) | E10: x (mm) | F10: y (mm) | G10: Gripper | H10: Load | I10: Notes
A11: T1 | C11: 250 | D11: -50 | E11: =C11*COS(RADIANS(D11)) | F11: =-C11*SIN(RADIANS(D11)) | G11: vertical | H11: 0 g
A12: T2 | C12: 250 | D12: -35 | E12: =C12*COS(RADIANS(D12)) | F12: =-C12*SIN(RADIANS(D12)) | G12: vertical | H12: 0 g
A13: T3 | C13: 250 | D13: 35 | E13: =C13*COS(RADIANS(D13)) | F13: =-C13*SIN(RADIANS(D13)) | G13: vertical | H13: 0 g
A14: T4 | C14: 250 | D14: 50 | E14: =C14*COS(RADIANS(D14)) | F14: =-C14*SIN(RADIANS(D14)) | G14: vertical | H14: 0 g
A15: T5 | C15: 350 | D15: -50 | E15: =C15*COS(RADIANS(D15)) | F15: =-C15*SIN(RADIANS(D15)) | G15: vertical | H15: 0 g
A16: T6 | C16: 350 | D16: -35 | E16: =C16*COS(RADIANS(D16)) | F16: =-C16*SIN(RADIANS(D16)) | G16: vertical | H16: 0 g
A17: T7 | C17: 350 | D17: 35 | E17: =C17*COS(RADIANS(D17)) | F17: =-C17*SIN(RADIANS(D17)) | G17: vertical | H17: 0 g
A18: T8 | C18: 350 | D18: 50 | E18: =C18*COS(RADIANS(D18)) | F18: =-C18*SIN(RADIANS(D18)) | G18: vertical | H18: 0 g
A19: T9 | C19: 300 | D19: 45 | E19: =C19*COS(RADIANS(D19)) | F19: =-C19*SIN(RADIANS(D19)) | G19: vertical | H19: 0 g | I19: R on the mat (repeatability target)
A20: T10 | C20: 300 | D20: 45 | E20: =C20*COS(RADIANS(D20)) | F20: =-C20*SIN(RADIANS(D20)) | G20: vertical | H20: 500 g | I20: T9 position with 500 g in the gripper
A21: T11 | C21: 350 | D21: 35 | E21: =C21*COS(RADIANS(D21)) | F21: =-C21*SIN(RADIANS(D21)) | G21: vertical | H21: 500 g | I21: T7 position (far) with 500 g: worst-case sag
A22: Targets match WDD2_target_mat_A4x4.pdf. Robot frame: x forward from the base axis, y to the LEFT; base angle + = to the RIGHT (seen from behind the arm), so y = −r·sin(angle). All targets are outside ±30° on the base (horn-play hunting zone).
A24: Approaches
A25: Target | B25: Trial | C25: Radial (mm, + = beyond target) | D25: Lateral (mm, + = right of ray) | E25: Centroid radial | F25: Centroid lateral | G25: l = dist. to centroid | H25: (l − mean l)² | I25: Note
A26: T1 | B26: 1 | C26: -2 | D26: 6 | E26: =IF(ISNUMBER(C26),AVERAGEIFS($C$26:$C$155,$A$26:$A$155,A26),"") | F26: =IF(ISNUMBER(D26),AVERAGEIFS($D$26:$D$155,$A$26:$A$155,A26),"") | G26: =IF(AND(ISNUMBER(C26),ISNUMBER(D26)),SQRT((C26-E26)^2+(D26-F26)^2),"") | H26: =IF(ISNUMBER(G26),(G26-AVERAGEIFS($G$26:$G$155,$A$26:$A$155,A26))^2,"")
A27: T1 | B27: 2 | C27: -1 | D27: 2 | E27: =IF(ISNUMBER(C27),AVERAGEIFS($C$26:$C$155,$A$26:$A$155,A27),"") | F27: =IF(ISNUMBER(D27),AVERAGEIFS($D$26:$D$155,$A$26:$A$155,A27),"") | G27: =IF(AND(ISNUMBER(C27),ISNUMBER(D27)),SQRT((C27-E27)^2+(D27-F27)^2),"") | H27: =IF(ISNUMBER(G27),(G27-AVERAGEIFS($G$26:$G$155,$A$26:$A$155,A27))^2,"")
A28: T1 | B28: 3 | C28: -1 | D28: 4 | E28: =IF(ISNUMBER(C28),AVERAGEIFS($C$26:$C$155,$A$26:$A$155,A28),"") | F28: =IF(ISNUMBER(D28),AVERAGEIFS($D$26:$D$155,$A$26:$A$155,A28),"") | G28: =IF(AND(ISNUMBER(C28),ISNUMBER(D28)),SQRT((C28-E28)^2+(D28-F28)^2),"") | H28: =IF(ISNUMBER(G28),(G28-AVERAGEIFS($G$26:$G$155,$A$26:$A$155,A28))^2,"")
A29: T1 | B29: 4 | C29: -4 | D29: 2 | E29: =IF(ISNUMBER(C29),AVERAGEIFS($C$26:$C$155,$A$26:$A$155,A29),"") | F29: =IF(ISNUMBER(D29),AVERAGEIFS($D$26:$D$155,$A$26:$A$155,A29),"") | G29: =IF(AND(ISNUMBER(C29),ISNUMBER(D29)),SQRT((C29-E29)^2+(D29-F29)^2),"") | H29: =IF(ISNUMBER(G29),(G29-AVERAGEIFS($G$26:$G$155,$A$26:$A$155,A29))^2,"")
A30: T1 | B30: 5 | C30: -5 | D30: 2 | E30: =IF(ISNUMBER(C30),AVERAGEIFS($C$26:$C$155,$A$26:$A$155,A30),"") | F30: =IF(ISNUMBER(D30),AVERAGEIFS($D$26:$D$155,$A$26:$A$155,A30),"") | G30: =IF(AND(ISNUMBER(C30),ISNUMBER(D30)),SQRT((C30-E30)^2+(D30-F30)^2),"") | H30: =IF(ISNUMBER(G30),(G30-AVERAGEIFS($G$26:$G$155,$A$26:$A$155,A30))^2,"")
A31: T1 | B31: 6 | C31: -5 | D31: 3 | E31: =IF(ISNUMBER(C31),AVERAGEIFS($C$26:$C$155,$A$26:$A$155,A31),"") | F31: =IF(ISNUMBER(D31),AVERAGEIFS($D$26:$D$155,$A$26:$A$155,A31),"") | G31: =IF(AND(ISNUMBER(C31),ISNUMBER(D31)),SQRT((C31-E31)^2+(D31-F31)^2),"") | H31: =IF(ISNUMBER(G31),(G31-AVERAGEIFS($G$26:$G$155,$A$26:$A$155,A31))^2,"")
A32: T1 | B32: 7 | C32: -6 | D32: 2 | E32: =IF(ISNUMBER(C32),AVERAGEIFS($C$26:$C$155,$A$26:$A$155,A32),"") | F32: =IF(ISNUMBER(D32),AVERAGEIFS($D$26:$D$155,$A$26:$A$155,A32),"") | G32: =IF(AND(ISNUMBER(C32),ISNUMBER(D32)),SQRT((C32-E32)^2+(D32-F32)^2),"") | H32: =IF(ISNUMBER(G32),(G32-AVERAGEIFS($G$26:$G$155,$A$26:$A$155,A32))^2,"")
A33: T1 | B33: 8 | C33: -4 | D33: 1 | E33: =IF(ISNUMBER(C33),AVERAGEIFS($C$26:$C$155,$A$26:$A$155,A33),"") | F33: =IF(ISNUMBER(D33),AVERAGEIFS($D$26:$D$155,$A$26:$A$155,A33),"") | G33: =IF(AND(ISNUMBER(C33),ISNUMBER(D33)),SQRT((C33-E33)^2+(D33-F33)^2),"") | H33: =IF(ISNUMBER(G33),(G33-AVERAGEIFS($G$26:$G$155,$A$26:$A$155,A33))^2,"")
A34: T1 | B34: 9 | C34: -2 | D34: 0 | E34: =IF(ISNUMBER(C34),AVERAGEIFS($C$26:$C$155,$A$26:$A$155,A34),"") | F34: =IF(ISNUMBER(D34),AVERAGEIFS($D$26:$D$155,$A$26:$A$155,A34),"") | G34: =IF(AND(ISNUMBER(C34),ISNUMBER(D34)),SQRT((C34-E34)^2+(D34-F34)^2),"") | H34: =IF(ISNUMBER(G34),(G34-AVERAGEIFS($G$26:$G$155,$A$26:$A$155,A34))^2,"")
A35: T1 | B35: 10 | C35: 0 | D35: 2 | E35: =IF(ISNUMBER(C35),AVERAGEIFS($C$26:$C$155,$A$26:$A$155,A35),"") | F35: =IF(ISNUMBER(D35),AVERAGEIFS($D$26:$D$155,$A$26:$A$155,A35),"") | G35: =IF(AND(ISNUMBER(C35),ISNUMBER(D35)),SQRT((C35-E35)^2+(D35-F35)^2),"") | H35: =IF(ISNUMBER(G35),(G35-AVERAGEIFS($G$26:$G$155,$A$26:$A$155,A35))^2,"")
A36: T2 | B36: 1 | C36: 0 | D36: 0 | E36: =IF(ISNUMBER(C36),AVERAGEIFS($C$26:$C$155,$A$26:$A$155,A36),"") | F36: =IF(ISNUMBER(D36),AVERAGEIFS($D$26:$D$155,$A$26:$A$155,A36),"") | G36: =IF(AND(ISNUMBER(C36),ISNUMBER(D36)),SQRT((C36-E36)^2+(D36-F36)^2),"") | H36: =IF(ISNUMBER(G36),(G36-AVERAGEIFS($G$26:$G$155,$A$26:$A$155,A36))^2,"")
A37: T2 | B37: 2 | C37: -2 | D37: -1 | E37: =IF(ISNUMBER(C37),AVERAGEIFS($C$26:$C$155,$A$26:$A$155,A37),"") | F37: =IF(ISNUMBER(D37),AVERAGEIFS($D$26:$D$155,$A$26:$A$155,A37),"") | G37: =IF(AND(ISNUMBER(C37),ISNUMBER(D37)),SQRT((C37-E37)^2+(D37-F37)^2),"") | H37: =IF(ISNUMBER(G37),(G37-AVERAGEIFS($G$26:$G$155,$A$26:$A$155,A37))^2,"")
... A114: T9 | B114: 9 | C114: -4 | D114: -3 | E114: =IF(ISNUMBER(C114),AVERAGEIFS($C$26:$C$155,$A$26:$A$155,A114),"") | F114: =IF(ISNUMBER(D114),AVERAGEIFS($D$26:$D$155,$A$26:$A$155,A114),"") | G114: =IF(AND(ISNUMBER(C114),ISNUMBER(D114)),SQRT((C114-E114)^2+(D114-F114)^2),"") | H114: =IF(ISNUMBER(G114),(G114-AVERAGEIFS($G$26:$G$155,$A$26:$A$155,A114))^2,"")
A115: T9 | B115: 10 | E115: =IF(ISNUMBER(C115),AVERAGEIFS($C$26:$C$155,$A$26:$A$155,A115),"") | F115: =IF(ISNUMBER(D115),AVERAGEIFS($D$26:$D$155,$A$26:$A$155,A115),"") | G115: =IF(AND(ISNUMBER(C115),ISNUMBER(D115)),SQRT((C115-E115)^2+(D115-F115)^2),"") | H115: =IF(ISNUMBER(G115),(G115-AVERAGEIFS($G$26:$G$155,$A$26:$A$155,A115))^2,"") | I115: lateral not recorded (radial −4); trial left out
A116: T9 | B116: 11 | C116: -5 | D116: 0 | E116: =IF(ISNUMBER(C116),AVERAGEIFS($C$26:$C$155,$A$26:$A$155,A116),"") | F116: =IF(ISNUMBER(D116),AVERAGEIFS($D$26:$D$155,$A$26:$A$155,A116),"") | G116: =IF(AND(ISNUMBER(C116),ISNUMBER(D116)),SQRT((C116-E116)^2+(D116-F116)^2),"") | H116: =IF(ISNUMBER(G116),(G116-AVERAGEIFS($G$26:$G$155,$A$26:$A$155,A116))^2,"")
A117: T9 | B117: 12 | C117: -5 | D117: 2 | E117: =IF(ISNUMBER(C117),AVERAGEIFS($C$26:$C$155,$A$26:$A$155,A117),"") | F117: =IF(ISNUMBER(D117),AVERAGEIFS($D$26:$D$155,$A$26:$A$155,A117),"") | G117: =IF(AND(ISNUMBER(C117),ISNUMBER(D117)),SQRT((C117-E117)^2+(D117-F117)^2),"") | H117: =IF(ISNUMBER(G117),(G117-AVERAGEIFS($G$26:$G$155,$A$26:$A$155,A117))^2,"")
A118: T9 | B118: 13 | C118: -6 | D118: -2 | E118: =IF(ISNUMBER(C118),AVERAGEIFS($C$26:$C$155,$A$26:$A$155,A118),"") | F118: =IF(ISNUMBER(D118),AVERAGEIFS($D$26:$D$155,$A$26:$A$155,A118),"") | G118: =IF(AND(ISNUMBER(C118),ISNUMBER(D118)),SQRT((C118-E118)^2+(D118-F118)^2),"") | H118: =IF(ISNUMBER(G118),(G118-AVERAGEIFS($G$26:$G$155,$A$26:$A$155,A118))^2,"")
...

Sheet 8.7 Cycles
A1: 8.7 Pick-and-place cycles (R13; also R1, R3, R14)
A2: Saved JSON sequence in sequence mode, cycle times from the GUI cycle report.
A4: Setup: pick spot ≥ 300 mm from the base axis (R1), place spot at another base angle (both beyond ±25° of base home). Mark both on the mat. Wait times at pick and place ≥ 2 s (base settling).
A5: Success: the cube is picked, carried and released upright within the tolerance below of the place mark. Decide the tolerance before starting.
A6: Runs: 10 cycles with 50 g, 10 with 500 g. Film them. Export the GUI data after each set.
A7: Pass: at least 9 of 10 successful cycles per payload, each within 15 s.
A8: Legend: yellow cells = fill in during the test. Green cells = already measured during bring-up (keep or overwrite). White cells are formulas; do not type in them. The grey example row is not counted.
A9: Place tolerance (mm) | C9: 10 | D9: decide before testing
A10: Max cycle time (s) | C10: 15
A12: Payload | B12: Cycle | C12: Picked and placed upright (Y/N) | D12: Place error (mm) | E12: Cycle time (s) | F12: Success? | G12: Notes
A13: 50 g | B13: ex | C13: Y | D13: 6 | E13: 12.4 | F13: yes
A14: 50 g | B14: 1 | C14: Y | D14: 2.8 | E14: 11.71 | F14: =IF(C14="","",IF(AND(C14="Y",ISNUMBER(D14),D14<=$C$9,ISNUMBER(E14),E14<=$C$10),"yes","no")) | G14: radial +2, lateral -2 mm; GUI cycle 3, finished 21:37:38; gripper holding 0.127 A (meas)
A15: 50 g | B15: 2 | C15: Y | D15: 3.6 | E15: 11.8 | F15: =IF(C15="","",IF(AND(C15="Y",ISNUMBER(D15),D15<=$C$9,ISNUMBER(E15),E15<=$C$10),"yes","no")) | G15: radial +3, lateral -2 mm; GUI cycle 4, finished 21:39:12; gripper holding 0.129 A (meas)
A16: 50 g | B16: 3 | C16: Y | D16: 2.8 | E16: 11.84 | F16: =IF(C16="","",IF(AND(C16="Y",ISNUMBER(D16),D16<=$C$9,ISNUMBER(E16),E16<=$C$10),"yes","no")) | G16: radial +2, lateral -2 mm; GUI cycle 5, finished 21:42:06; gripper holding 0.105 A (meas)
A17: 50 g | B17: 4 | C17: Y | D17: 1 | E17: 12.06 | F17: =IF(C17="","",IF(AND(C17="Y",ISNUMBER(D17),D17<=$C$9,ISNUMBER(E17),E17<=$C$10),"yes","no")) | G17: radial +0, lateral -1 mm; GUI cycle 6, finished 21:42:52; gripper holding 0.115 A (meas)
A18: 50 g | B18: 5 | C18: Y | D18: 3 | E18: 11.85 | F18: =IF(C18="","",IF(AND(C18="Y",ISNUMBER(D18),D18<=$C$9,ISNUMBER(E18),E18<=$C$10),"yes","no")) | G18: radial +3, lateral +0 mm; GUI cycle 7, finished 21:43:41; gripper holding 0.118 A (meas)
A19: 50 g | B19: 6 | C19: Y | D19: 5 | E19: 11.83 | F19: =IF(C19="","",IF(AND(C19="Y",ISNUMBER(D19),D19<=$C$9,ISNUMBER(E19),E19<=$C$10),"yes","no")) | G19: radial +4, lateral -3 mm; GUI cycle 8, finished 21:44:30; gripper holding 0.127 A (meas); big oscillation on the way down
A20: 50 g | B20: 7 | C20: Y | D20: 4.5 | E20: 12.41 | F20: =IF(C20="","",IF(AND(C20="Y",ISNUMBER(D20),D20<=$C$9,ISNUMBER(E20),E20<=$C$10),"yes","no")) | G20: radial +4, lateral -2 mm; GUI cycle 10, finished 21:45:34; gripper holding 0.122 A (meas); big oscillation on the way down
A21: 50 g | B21: 8 | C21: Y | D21: 2.2 | E21: 11.95 | F21: =IF(C21="","",IF(AND(C21="Y",ISNUMBER(D21),D21<=$C$9,ISNUMBER(E21),E21<=$C$10),"yes","no")) | G21: radial +2, lateral -1 mm; GUI cycle 11, finished 21:46:27; gripper holding 0.125 A (meas)
A22: 50 g | B22: 9 | C22: Y | D22: 1 | E22: 12.25 | F22: =IF(C22="","",IF(AND(C22="Y",ISNUMBER(D22),D22<=$C$9,ISNUMBER(E22),E22<=$C$10),"yes","no")) | G22: radial +0, lateral -1 mm; GUI cycle 12, finished 21:47:12; gripper holding 0.119 A (meas)
A23: 50 g | B23: 10 | C23: Y | D23: 2.2 | E23: 12.49 | F23: =IF(C23="","",IF(AND(C23="Y",ISNUMBER(D23),D23<=$C$9,ISNUMBER(E23),E23<=$C$10),"yes","no")) | G23: radial +2, lateral -1 mm; GUI cycle 13, finished 21:48:17; gripper holding 0.103 A (meas)
A24: 500 g | B24: 1 | C24: Y | D24: 5.7 | E24: 12.42 | F24: =IF(C24="","",IF(AND(C24="Y",ISNUMBER(D24),D24<=$C$9,ISNUMBER(E24),E24<=$C$10),"yes","no")) | G24: radial -4, lateral +4 mm; GUI cycle 1; gripper holding 0.131 A (meas); big oscillation before drop
A25: 500 g | B25: 2 | C25: Y | D25: 2 | E25: 11.97 | F25: =IF(C25="","",IF(AND(C25="Y",ISNUMBER(D25),D25<=$C$9,ISNUMBER(E25),E25<=$C$10),"yes","no")) | G25: radial +0, lateral +2 mm; GUI cycle 3; gripper holding 0.157 A (meas)
... A33: 500 g | B33: 10 | C33: Y | D33: 2.8 | E33: 12.22 | F33: =IF(C33="","",IF(AND(C33="Y",ISNUMBER(D33),D33<=$C$9,ISNUMBER(E33),E33<=$C$10),"yes","no")) | G33: radial +2, lateral +2 mm; GUI cycle 12; gripper holding 0.132 A (meas); big oscillation before drop
A35: Summary
A36: Payload | B36: Cycles done | C36: Successes | D36: Mean time (s) | E36: Max time (s) | F36: Result
A37: 50 g | B37: =COUNTIFS($A$14:$A$33,"50 g",$F$14:$F$33,"yes")+COUNTIFS($A$14:$A$33,"50 g",$F$14:$F$33,"no") | C37: =COUNTIFS($A$14:$A$33,"50 g",$F$14:$F$33,"yes") | D37: =IFERROR(AVERAGEIFS($E$14:$E$33,$A$14:$A$33,"50 g"),"") | E37: =IF(B37=0,"",_xlfn.MAXIFS($E$14:$E$33,$A$14:$A$33,"50 g")) | F37: =IF(B37<10,"not done",IF(C37>=9,"PASS","FAIL"))
A38: 500 g | B38: =COUNTIFS($A$14:$A$33,"500 g",$F$14:$F$33,"yes")+COUNTIFS($A$14:$A$33,"500 g",$F$14:$F$33,"no") | C38: =COUNTIFS($A$14:$A$33,"500 g",$F$14:$F$33,"yes") | D38: =IFERROR(AVERAGEIFS($E$14:$E$33,$A$14:$A$33,"500 g"),"") | E38: =IF(B38=0,"",_xlfn.MAXIFS($E$14:$E$33,$A$14:$A$33,"500 g")) | F38: =IF(B38<10,"not done",IF(C38>=9,"PASS","FAIL"))
A39: All | F39: =IF(COUNTIF(F37:F38,"not done")>0,"not done",IF(COUNTIF(F37:F38,"FAIL")>0,"FAIL","PASS"))
A40: 13 Oct, 50 g, sequence test87_side_transfer (pick right station r 300 mm at -45 deg, place left station r 300 mm at +45 deg, above points z 100, 2 s waits). Export arm_export_20261013_215029.xlsx holds 13 GUI cycles: cycle 1 and 9 stopped (miss runs), cycle 2 = trial run before the set; cycles 3-8 and 10-13 are the 10 counted cycles. Model current columns in that export used cube mass 0.5 kg (GUI setting), not 50 g.
A41: Place error = sqrt(radial^2 + lateral^2) from the two components measured on the mat (8.6 convention: radial + beyond / - short, lateral + right / - left of the ray, seen from the base).
A43: Extra 500 g trials (run to check whether the oscillation affects accuracy; not counted in the summary above)
A44: Payload | B44: Cycle | C44: Picked and placed upright (Y/N) | D44: Place error (mm) | E44: Cycle time (s) | F44: Success? | G44: Notes
A45: 500 g | B45: 11 | C45: Y | D45: 2 | E45: 12.28 | F45: =IF(C45="","",IF(AND(C45="Y",ISNUMBER(D45),D45<=$C$9,ISNUMBER(E45),E45<=$C$10),"yes","no")) | G45: radial +0, lateral +2 mm; GUI cycle 13; gripper holding 0.132 A (meas)
A46: 500 g | B46: 12 | C46: Y | D46: 3 | E46: 12.41 | F46: =IF(C46="","",IF(AND(C46="Y",ISNUMBER(D46),D46<=$C$9,ISNUMBER(E46),E46<=$C$10),"yes","no")) | G46: radial +0, lateral +3 mm; GUI cycle 14; gripper holding 0.134 A (meas); big oscillation before drop
A47: 500 g | B47: 13 | C47: Y | D47: 3.6 | E47: 11.88 | F47: =IF(C47="","",IF(AND(C47="Y",ISNUMBER(D47),D47<=$C$9,ISNUMBER(E47),E47<=$C$10),"yes","no")) | G47: radial +2, lateral +3 mm; GUI cycle 15; gripper holding 0.134 A (meas)
A48: 500 g | B48: 14 | C48: Y | D48: 5 | E48: 12.03 | F48: =IF(C48="","",IF(AND(C48="Y",ISNUMBER(D48),D48<=$C$9,ISNUMBER(E48),E48<=$C$10),"yes","no")) | G48: radial -3, lateral +4 mm; GUI cycle 16; gripper holding 0.239 A (meas)
A49: 500 g | B49: 15 | C49: Y | D49: 3 | E49: 12.03 | F49: =IF(C49="","",IF(AND(C49="Y",ISNUMBER(D49),D49<=$C$9,ISNUMBER(E49),E49<=$C$10),"yes","no")) | G49: radial +0, lateral +3 mm; GUI cycle 17; gripper holding 0.139 A (meas); big oscillation before drop
A51: Oscillation check (all 25 cycles, place error = sqrt(radial^2 + lateral^2))
A52: Group | B52: n | C52: Mean error (mm) | D52: Max error (mm) | E52: Mean radial (mm) | F52: Mean lateral (mm)
...

Sheet 8.8 Power & safety
A1: 8.8 Power, temperature and safety (R2, R4, R5, R6, R7, Objective 2)
A2: Do the E-stop runs over something soft: the arm drops when servo power is cut.
A4: Full extension (R2): hold 500 g with the arm fully extended for 30 s. Record whether it holds, the sag and the servo case temperatures afterwards.
A5: Rails (R5): multimeter at idle, while holding 500 g extended, and the lowest reading during a fast move. Check the rating limits against each datasheet before testing.
A6: E-stop (R7): press it 10 times during motion. Then one run with the E-stop signal wire to GPIO 41 disconnected: the relay must still cut the servo power.
A7: Fuse (R6): confirm it never blew. Polarity protection and transient suppression: by inspection only (do not reverse the supply).
A8: Legend: yellow cells = fill in during the test. Green cells = already measured during bring-up (keep or overwrite). White cells are formulas; do not type in them. The grey example row is not counted.
A9: Full extension hold (R2)
A10: Quantity | B10: Value | C10: Unit | D10: Note
A11: Held 500 g for 30 s (Y/N) | B11: Y | D11: 13 Oct: W,0,0,0,0 (all joints horizontal), 500 g cube, grasp confirmed (median 0.142 A), still holding at the check (0.109 A).
A12: Sag at the tip | B12: 15 | C12: mm | D12: Pad centre 65 mm above table empty, 50 mm loaded (ruler).
A13: Shoulder encoder change | B13: -0.75 | C13: ° | D13: 0.13 -> -0.62 deg; trim at its +5.00 deg clamp (was +2.33 empty)
A14: Elbow encoder change | B14: -0.63 | C14: ° | D14: -0.25 -> -0.88 deg; trim at its +5.00 deg clamp (was +2.39 empty). Wrist -0.09 -> -0.18 deg, trim -0.23 -> +1.72.
A15: Result | B15: =IF(B11="","not done",IF(B11="Y","PASS","FAIL"))
A16: Encoder changes account for ~9 mm of the 15 mm sag (0.75 deg x 453 mm + 0.63 deg x 278 mm + 0.09 deg x 133 mm); the rest is bending/play downstream of the encoders (wrist bracket, gripper, cube in the pads). Shoulder and elbow trims saturate at the 5 deg clamp, so this pose with 500 g is at the limit of what the trim loop can correct.
A17: Rail voltages (R5)
A18: Rail | B18: Rating min (V) | C18: Rating max (V) | D18: Idle (V) | E18: Holding 500 g extended (V) | F18: Lowest in fast move (V) | G18: Result | H18: Notes
A19: #1 shoulder (DS5180), 8.0 V | B19: 6 | C19: 8.4 | D19: 8.12 | E19: 8.05 | F19: 7.78 | G19: =IF(OR(NOT(ISNUMBER(B19)),NOT(ISNUMBER(C19)),NOT(ISNUMBER(E19)),NOT(ISNUMBER(F19))),"not done",IF(AND(MIN(D19:F19)>=B19,MAX(D19:F19)<=C19),"PASS","FAIL")) | H19: idle: bring-up 9 Oct; holding: 13 Oct W,0,0,0,0 + 500 g; fast move: one 8.7 cycle with 500 g, phone video of the meter: min 7.78 V in the side transfer, max 8.08 V while lowering the cube
A20: #2 base and elbow (DS3240), 6.7 V | B20: 4.8 | C20: 6.8 | D20: 6.67 | E20: 6.63 | F20: 6.65 | G20: =IF(OR(NOT(ISNUMBER(B20)),NOT(ISNUMBER(C20)),NOT(ISNUMBER(E20)),NOT(ISNUMBER(F20))),"not done",IF(AND(MIN(D20:F20)>=B20,MAX(D20:F20)<=C20),"PASS","FAIL")) | H20: idle: bring-up 9 Oct; holding: 13 Oct W,0,0,0,0 + 500 g; fast move: one 8.7 cycle with 500 g, phone video of the meter: 6.65-6.66 V throughout (elbow loads on the descents, base on the side transfer, so the peaks do not coincide)
A21: #3 wrist and gripper (DS3225, MG996R), 6.5 V | B21: 4.8 | C21: 6.8 | D21: 6.54 | E21: 6.5 | F21: 6.51 | G21: =IF(OR(NOT(ISNUMBER(B21)),NOT(ISNUMBER(C21)),NOT(ISNUMBER(E21)),NOT(ISNUMBER(F21))),"not done",IF(AND(MIN(D21:F21)>=B21,MAX(D21:F21)<=C21),"PASS","FAIL")) | H21: idle: bring-up 9 Oct; holding: 13 Oct W,0,0,0,0 + 500 g; fast move: one 8.7 cycle with 500 g, phone video of the meter: min 6.51 V in the side transfer, max 6.53 V on the descents and pickup
A22: 5 V logic | B22: 4.75 | C22: 5.25 | D22: 5.15 | E22: 5.06 | F22: 5.15 | G22: =IF(OR(NOT(ISNUMBER(B22)),NOT(ISNUMBER(C22)),NOT(ISNUMBER(E22)),NOT(ISNUMBER(F22))),"not done",IF(AND(MIN(D22:F22)>=B22,MAX(D22:F22)<=C22),"PASS","FAIL")) | H22: idle: bring-up 9 Oct; holding: 13 Oct 5.06 V; fast move: flat at 5.15 V over one 8.7 cycle with 500 g (phone video of the meter)
A23: All rails | G23: =IF(COUNTIF(G19:G22,"not done")>0,"not done",IF(COUNTIF(G19:G22,"FAIL")>0,"FAIL","PASS"))
A24: Ratings B19:C22 are the typical published ranges (DS5180 6.0-8.4 V; DS3240 and DS3225 4.8-6.8 V; MG996R 4.8-7.2 V so rail 3 uses the narrower DS3225 range; 5 V USB-level input 4.75-5.25 V). Confirm each against your own datasheet before quoting. Fast-move values: lowest/highest reading on a handheld multimeter (display ~3 updates/s, phone video), so short transients are not captured.
A25: Servo case temperatures
A26: Servo | B26: After 10 cycles (°C) | C26: After 5 min hold extended (°C) | D26: Limit (°C) | E26: Result | F26: Baseline, holding home (°C) | G26: Rise over room (°C) | H26: Rise over room after cycles (°C) | I26: Rise over room after 5 min hold (°C)
A27: Base (DS3240) | B27: 19.5 | C27: 21.3 | D27: 60 | E27: =IF(AND(NOT(ISNUMBER(B27)),NOT(ISNUMBER(C27))),"not done",IF(MAX(B27:C27)<=D27,"PASS","FAIL")) | F27: 21.3 | G27: =F27-$B$54 | H27: =B27-$E$54 | I27: =C27-$H$54
A28: Shoulder (DS5180) | B28: 23.9 | C28: 32.1 | D28: 60 | E28: =IF(AND(NOT(ISNUMBER(B28)),NOT(ISNUMBER(C28))),"not done",IF(MAX(B28:C28)<=D28,"PASS","FAIL")) | F28: 23.3 | G28: =F28-$B$54 | H28: =B28-$E$54 | I28: =C28-$H$54
A29: Elbow (DS3240) | B29: 29.8 | C29: 54.5 | D29: 60 | E29: =IF(AND(NOT(ISNUMBER(B29)),NOT(ISNUMBER(C29))),"not done",IF(MAX(B29:C29)<=D29,"PASS","FAIL")) | F29: 27.7 | G29: =F29-$B$54 | H29: =B29-$E$54 | I29: =C29-$H$54
A30: Wrist (DS3225) | B30: 19.4 | C30: 23.4 | D30: 60 | E30: =IF(AND(NOT(ISNUMBER(B30)),NOT(ISNUMBER(C30))),"not done",IF(MAX(B30:C30)<=D30,"PASS","FAIL")) | F30: 20.9 | G30: =F30-$B$54 | H30: =B30-$E$54 | I30: =C30-$H$54
A31: Gripper (MG996R) | B31: 19.7 | C31: 21.7 | D31: 60 | E31: =IF(AND(NOT(ISNUMBER(B31)),NOT(ISNUMBER(C31))),"not done",IF(MAX(B31:C31)<=D31,"PASS","FAIL")) | F31: 21 | G31: =F31-$B$54 | H31: =B31-$E$54 | I31: =C31-$H$54
A32: All servos | E32: =IF(COUNTIF(E27:E31,"not done")>0,"not done",IF(COUNTIF(E27:E31,"FAIL")>0,"FAIL","PASS"))
A33: Limit 60 °C is an assumed safe case temperature for PLA-CF mounts and the servos; change it if you use a datasheet value. After 5 min hold = W,0,0,0,0 with 500 g for 5 min (13 Oct), room 19.0 °C (H54). Elbow 54.5 °C is the closest to the limit.
A34: After 10 cycles = measured ~5 min after the last 8.7 cycle (13 Oct, 25 cycles in total incl. 15 with 500 g), room 19.0 °C (E54).
A35: E-stop (R7)
A36: Press | B36: Servo rail after press (V) | C36: 5 V logic stays on (Y/N) | D36: GUI shows E-stop (Y/N) | E36: No restart until Reset (Y/N) | F36: Result | G36: Stop time (s, phone video) | H36: Notes
A37: 1 | B37: 0 | C37: Y | D37: Y | E37: Y | F37: =IF(B37="","not done",IF(AND(B37<0.5,C37="Y",OR(D37="Y",D37="—"),E37="Y"),"PASS","FAIL")) | G37: 0.20–0.34 over the 10 presses | H37: 13 Oct: pressed during motion; 0 V on each servo rail every time, GUI showed E-stop every time; ESP and 5 V stayed on throughout; arm only resumed after the E-stop latch was released AND Reset was pressed in the GUI.
A38: 2 | B38: 0 | C38: Y | D38: Y | E38: Y | F38: =IF(B38="","not done",IF(AND(B38<0.5,C38="Y",OR(D38="Y",D38="—"),E38="Y"),"PASS","FAIL"))
A39: 3 | B39: 0 | C39: Y | D39: Y | E39: Y | F39: =IF(B39="","not done",IF(AND(B39<0.5,C39="Y",OR(D39="Y",D39="—"),E39="Y"),"PASS","FAIL"))
A40: 4 | B40: 0 | C40: Y | D40: Y | E40: Y | F40: =IF(B40="","not done",IF(AND(B40<0.5,C40="Y",OR(D40="Y",D40="—"),E40="Y"),"PASS","FAIL"))
A41: 5 | B41: 0 | C41: Y | D41: Y | E41: Y | F41: =IF(B41="","not done",IF(AND(B41<0.5,C41="Y",OR(D41="Y",D41="—"),E41="Y"),"PASS","FAIL"))
...
